2024-11-05 23:11:17,976 - fastAPI - INFO - HP-API - local - Incoming request: GET http://127.0.0.1:8855/.
2024-11-05 23:11:17,978 - fastAPI - INFO - HP-API - local - Handling function: redirect_to_ap
2024-11-05 23:11:17,981 - fastAPI - INFO - HP-API - local - Completed request in 0.0017 seconds
2024-11-05 23:11:17,987 - fastAPI - INFO - HP-API - local - Response status code: 307
2024-11-05 23:11:34,398 - fastAPI - INFO - HP-API - local - Incoming request: GET http://127.0.0.1:8855/.
2024-11-05 23:11:34,400 - fastAPI - INFO - HP-API - local - Handling function: redirect_to_ap
2024-11-05 23:11:34,401 - fastAPI - INFO - HP-API - local - Completed request in 0.0008 seconds
2024-11-05 23:11:34,403 - fastAPI - INFO - HP-API - local - Response status code: 307
2024-11-05 23:12:32,088 - fastAPI - INFO - HP-API - local - Incoming request: GET http://127.0.0.1:8855/users.
2024-11-05 23:12:32,090 - fastAPI - INFO - HP-API - local - Handling function: unknown
2024-11-05 23:12:32,091 - fastAPI - INFO - HP-API - local - Completed request in 0.0012 seconds
2024-11-05 23:12:32,092 - fastAPI - INFO - HP-API - local - Response status code: 404
2024-11-05 23:12:32,409 - fastAPI - INFO - HP-API - local - Incoming request: GET http://127.0.0.1:8855/favicon.ico.
2024-11-05 23:12:32,410 - fastAPI - INFO - HP-API - local - Handling function: unknown
2024-11-05 23:12:32,414 - fastAPI - INFO - HP-API - local - Completed request in 0.0042 seconds
2024-11-05 23:12:32,415 - fastAPI - INFO - HP-API - local - Response status code: 404
2024-11-05 23:13:28,620 - fastAPI - INFO - HP-API - local - Incoming request: GET http://127.0.0.1:8855/users.
2024-11-05 23:13:28,621 - fastAPI - INFO - HP-API - local - Handling function: unknown
2024-11-05 23:13:28,622 - fastAPI - INFO - HP-API - local - Completed request in 0.0007 seconds
2024-11-05 23:13:28,622 - fastAPI - INFO - HP-API - local - Response status code: 404
2024-11-05 23:13:28,708 - fastAPI - INFO - HP-API - local - Incoming request: GET http://127.0.0.1:8855/favicon.ico.
2024-11-05 23:13:28,709 - fastAPI - INFO - HP-API - local - Handling function: unknown
2024-11-05 23:13:28,710 - fastAPI - INFO - HP-API - local - Completed request in 0.0006 seconds
2024-11-05 23:13:28,719 - fastAPI - INFO - HP-API - local - Response status code: 404
2024-11-05 23:13:30,016 - fastAPI - INFO - HP-API - local - Incoming request: GET http://127.0.0.1:8855/users.
2024-11-05 23:13:30,019 - fastAPI - INFO - HP-API - local - Handling function: unknown
2024-11-05 23:13:30,020 - fastAPI - INFO - HP-API - local - Completed request in 0.0006 seconds
2024-11-05 23:13:30,020 - fastAPI - INFO - HP-API - local - Response status code: 404
2024-11-05 23:13:30,131 - fastAPI - INFO - HP-API - local - Incoming request: GET http://127.0.0.1:8855/favicon.ico.
2024-11-05 23:13:30,131 - fastAPI - INFO - HP-API - local - Handling function: unknown
2024-11-05 23:13:30,133 - fastAPI - INFO - HP-API - local - Completed request in 0.0010 seconds
2024-11-05 23:13:30,134 - fastAPI - INFO - HP-API - local - Response status code: 404
2024-11-05 23:15:53,237 - fastAPI - INFO - HP-API - local - Incoming request: GET http://127.0.0.1:8855/v1/users.
2024-11-05 23:15:53,238 - fastAPI - INFO - HP-API - local - Handling function: read_users
2024-11-05 23:15:53,240 - fastAPI - INFO - HP-API - local - Completed request in 0.0007 seconds
2024-11-05 23:15:53,241 - fastAPI - INFO - HP-API - local - Response status code: 200
2024-11-05 23:15:53,522 - fastAPI - INFO - HP-API - local - Incoming request: GET http://127.0.0.1:8855/favicon.ico.
2024-11-05 23:15:53,525 - fastAPI - INFO - HP-API - local - Handling function: unknown
2024-11-05 23:15:53,527 - fastAPI - INFO - HP-API - local - Completed request in 0.0007 seconds
2024-11-05 23:15:53,528 - fastAPI - INFO - HP-API - local - Response status code: 404
2024-12-10 18:53:08,722 - fastAPI - INFO - HP-API - local - Incoming request: GET http://127.0.0.1:8855/.
2024-12-10 18:53:08,726 - fastAPI - INFO - HP-API - local - Handling function: redirect_to_ap
2024-12-10 18:53:08,728 - fastAPI - INFO - HP-API - local - Completed request in 0.0011 seconds
2024-12-10 18:53:08,742 - fastAPI - INFO - HP-API - local - Response status code: 307
2024-12-10 18:53:33,793 - fastAPI - INFO - HP-API - local - Incoming request: GET http://127.0.0.1:8855/docs/.
2024-12-10 18:53:33,795 - fastAPI - INFO - HP-API - local - Handling function: unknown
2024-12-10 18:53:33,797 - fastAPI - INFO - HP-API - local - Completed request in 0.0007 seconds
2024-12-10 18:53:33,807 - fastAPI - INFO - HP-API - local - Response status code: 307
2024-12-10 18:53:33,821 - fastAPI - INFO - HP-API - local - Incoming request: GET http://127.0.0.1:8855/docs.
2024-12-10 18:53:33,823 - fastAPI - INFO - HP-API - local - Handling function: swagger_ui_html
2024-12-10 18:53:33,825 - fastAPI - INFO - HP-API - local - Completed request in 0.0010 seconds
2024-12-10 18:53:33,831 - fastAPI - INFO - HP-API - local - Response status code: 200
2024-12-10 18:53:34,559 - fastAPI - INFO - HP-API - local - Incoming request: GET http://127.0.0.1:8855/openapi.json.
2024-12-10 18:53:34,560 - fastAPI - INFO - HP-API - local - Handling function: openapi
2024-12-10 18:53:34,618 - fastAPI - INFO - HP-API - local - Completed request in 0.0568 seconds
2024-12-10 18:53:34,619 - fastAPI - INFO - HP-API - local - Response status code: 200
2024-12-10 18:54:05,816 - fastAPI - INFO - HP-API - local - Incoming request: GET http://127.0.0.1:8855/v1/users.
2024-12-10 18:54:05,816 - fastAPI - INFO - HP-API - local - Handling function: read_users
2024-12-10 18:54:05,837 - fastAPI - ERROR - HP-API - local - Error processing request. Request was handled by: read_users 
Method: GET - URL: http://127.0.0.1:8855/v1/users - Headers: Headers({'host': '127.0.0.1:8855', 'user-agent': 'Mozilla/5.0 (X11; Linux x86_64; rv:133.0) Gecko/20100101 Firefox/133.0', 'accept': 'application/json', 'accept-language': 'en-US,en;q=0.5', 'accept-encoding': 'gzip, deflate, br, zstd', 'referer': 'http://127.0.0.1:8855/docs', 'connection': 'keep-alive', 'sec-fetch-dest': 'empty', 'sec-fetch-mode': 'cors', 'sec-fetch-site': 'same-origin', 'priority': 'u=0'}) 
Stack Trace: 'MySQL' object has no attribute 'execute'
Traceback (most recent call last):
  File "/home/n8/.local/lib/python3.10/site-packages/starlette/middleware/base.py", line 157, in call_next
    message = await recv_stream.receive()
  File "/home/n8/.local/lib/python3.10/site-packages/anyio/streams/memory.py", line 111, in receive
    return self.receive_nowait()
  File "/home/n8/.local/lib/python3.10/site-packages/anyio/streams/memory.py", line 104, in receive_nowait
    raise EndOfStream
anyio.EndOfStream

During handling of the above exception, another exception occurred:

Traceback (most recent call last):
  File "/home/n8/Documents/capstone/OSUCS461-ExitTicket/OSUCS461/main.py", line 32, in dispatch
    response = await call_next(request)
  File "/home/n8/.local/lib/python3.10/site-packages/starlette/middleware/base.py", line 163, in call_next
    raise app_exc
  File "/home/n8/.local/lib/python3.10/site-packages/starlette/middleware/base.py", line 149, in coro
    await self.app(scope, receive_or_disconnect, send_no_error)
  File "/home/n8/.local/lib/python3.10/site-packages/starlette/middleware/exceptions.py", line 62, in __call__
    await wrap_app_handling_exceptions(self.app, conn)(scope, receive, send)
  File "/home/n8/.local/lib/python3.10/site-packages/starlette/_exception_handler.py", line 53, in wrapped_app
    raise exc
  File "/home/n8/.local/lib/python3.10/site-packages/starlette/_exception_handler.py", line 42, in wrapped_app
    await app(scope, receive, sender)
  File "/home/n8/.local/lib/python3.10/site-packages/starlette/routing.py", line 715, in __call__
    await self.middleware_stack(scope, receive, send)
  File "/home/n8/.local/lib/python3.10/site-packages/starlette/routing.py", line 735, in app
    await route.handle(scope, receive, send)
  File "/home/n8/.local/lib/python3.10/site-packages/starlette/routing.py", line 288, in handle
    await self.app(scope, receive, send)
  File "/home/n8/.local/lib/python3.10/site-packages/starlette/routing.py", line 76, in app
    await wrap_app_handling_exceptions(app, request)(scope, receive, send)
  File "/home/n8/.local/lib/python3.10/site-packages/starlette/_exception_handler.py", line 53, in wrapped_app
    raise exc
  File "/home/n8/.local/lib/python3.10/site-packages/starlette/_exception_handler.py", line 42, in wrapped_app
    await app(scope, receive, sender)
  File "/home/n8/.local/lib/python3.10/site-packages/starlette/routing.py", line 73, in app
    response = await f(request)
  File "/home/n8/.local/lib/python3.10/site-packages/fastapi/routing.py", line 301, in app
    raw_response = await run_endpoint_function(
  File "/home/n8/.local/lib/python3.10/site-packages/fastapi/routing.py", line 212, in run_endpoint_function
    return await dependant.call(**values)
  File "/home/n8/Documents/capstone/OSUCS461-ExitTicket/OSUCS461/Routers/v1.py", line 13, in read_users
    return UserLogic.read()
  File "/home/n8/Documents/capstone/OSUCS461-ExitTicket/OSUCS461/Classes/Database/__init__.py", line 22, in read
    return DB.execute(query)
AttributeError: 'MySQL' object has no attribute 'execute'

2024-12-10 18:54:05,845 - fastAPI - INFO - HP-API - local - Completed request in 0.0280 seconds
2024-12-10 19:00:31,079 - fastAPI - INFO - HP-API - local - Incoming request: GET http://127.0.0.1:8855/openapi.json.
2024-12-10 19:00:31,081 - fastAPI - INFO - HP-API - local - Handling function: openapi
2024-12-10 19:00:31,142 - fastAPI - INFO - HP-API - local - Completed request in 0.0598 seconds
2024-12-10 19:00:31,146 - fastAPI - INFO - HP-API - local - Response status code: 200
2024-12-10 19:00:35,387 - fastAPI - INFO - HP-API - local - Incoming request: GET http://127.0.0.1:8855/v1/users.
2024-12-10 19:00:35,388 - fastAPI - INFO - HP-API - local - Handling function: read_users
2024-12-10 19:00:35,401 - fastAPI - INFO - HP-API - local - Completed request in 0.0121 seconds
2024-12-10 19:00:35,401 - fastAPI - INFO - HP-API - local - Response status code: 200
2024-12-10 19:02:41,968 - fastAPI - INFO - HP-API - local - Incoming request: GET http://127.0.0.1:8855/docs.
2024-12-10 19:02:41,972 - fastAPI - INFO - HP-API - local - Handling function: swagger_ui_html
2024-12-10 19:02:41,980 - fastAPI - INFO - HP-API - local - Completed request in 0.0072 seconds
2024-12-10 19:02:41,981 - fastAPI - INFO - HP-API - local - Response status code: 200
2024-12-10 19:02:42,460 - fastAPI - INFO - HP-API - local - Incoming request: GET http://127.0.0.1:8855/openapi.json.
2024-12-10 19:02:42,462 - fastAPI - INFO - HP-API - local - Handling function: openapi
2024-12-10 19:02:42,528 - fastAPI - INFO - HP-API - local - Completed request in 0.0661 seconds
2024-12-10 19:02:42,531 - fastAPI - INFO - HP-API - local - Response status code: 200
2024-12-10 19:02:50,736 - fastAPI - INFO - HP-API - local - Incoming request: GET http://127.0.0.1:8855/v1/users.
2024-12-10 19:02:50,737 - fastAPI - INFO - HP-API - local - Handling function: read_users
2024-12-10 19:02:50,739 - fastAPI - INFO - HP-API - local - Completed request in 0.0019 seconds
2024-12-10 19:02:50,739 - fastAPI - INFO - HP-API - local - Response status code: 404
2024-12-10 19:09:25,530 - fastAPI - INFO - HP-API - local - Incoming request: GET http://127.0.0.1:8855/v1/users.
2024-12-10 19:09:25,531 - fastAPI - INFO - HP-API - local - Handling function: read_users
2024-12-10 19:09:25,534 - fastAPI - INFO - HP-API - local - Completed request in 0.0025 seconds
2024-12-10 19:09:25,535 - fastAPI - INFO - HP-API - local - Response status code: 404
2024-12-10 19:09:25,572 - fastAPI - INFO - HP-API - local - Incoming request: GET http://127.0.0.1:8855/v1/users/1.
2024-12-10 19:09:25,573 - fastAPI - INFO - HP-API - local - Handling function: read_user
2024-12-10 19:09:25,580 - fastAPI - INFO - HP-API - local - Completed request in 0.0060 seconds
2024-12-10 19:09:25,580 - fastAPI - INFO - HP-API - local - Response status code: 404
2024-12-10 19:09:25,595 - fastAPI - INFO - HP-API - local - Incoming request: POST http://127.0.0.1:8855/v1/users.
2024-12-10 19:09:25,596 - fastAPI - INFO - HP-API - local - Handling function: write_user
2024-12-10 19:09:25,605 - fastAPI - ERROR - HP-API - local - Error processing request. Request was handled by: write_user 
Method: POST - URL: http://127.0.0.1:8855/v1/users - Headers: Headers({'host': '127.0.0.1:8855', 'user-agent': 'curl/7.81.0', 'accept': '*/*', 'content-type': 'application/json', 'content-length': '57'}) 
Stack Trace: BaseModel.__init__() takes 1 positional argument but 4 were given
Traceback (most recent call last):
  File "/home/n8/.local/lib/python3.10/site-packages/anyio/streams/memory.py", line 111, in receive
    return self.receive_nowait()
  File "/home/n8/.local/lib/python3.10/site-packages/anyio/streams/memory.py", line 106, in receive_nowait
    raise WouldBlock
anyio.WouldBlock

During handling of the above exception, another exception occurred:

Traceback (most recent call last):
  File "/home/n8/.local/lib/python3.10/site-packages/anyio/streams/memory.py", line 124, in receive
    return receiver.item
AttributeError: 'MemoryObjectItemReceiver' object has no attribute 'item'

During handling of the above exception, another exception occurred:

Traceback (most recent call last):
  File "/home/n8/.local/lib/python3.10/site-packages/starlette/middleware/base.py", line 157, in call_next
    message = await recv_stream.receive()
  File "/home/n8/.local/lib/python3.10/site-packages/anyio/streams/memory.py", line 126, in receive
    raise EndOfStream
anyio.EndOfStream

During handling of the above exception, another exception occurred:

Traceback (most recent call last):
  File "/home/n8/Documents/capstone/OSUCS461-ExitTicket/OSUCS461/main.py", line 32, in dispatch
    response = await call_next(request)
  File "/home/n8/.local/lib/python3.10/site-packages/starlette/middleware/base.py", line 163, in call_next
    raise app_exc
  File "/home/n8/.local/lib/python3.10/site-packages/starlette/middleware/base.py", line 149, in coro
    await self.app(scope, receive_or_disconnect, send_no_error)
  File "/home/n8/.local/lib/python3.10/site-packages/starlette/middleware/exceptions.py", line 62, in __call__
    await wrap_app_handling_exceptions(self.app, conn)(scope, receive, send)
  File "/home/n8/.local/lib/python3.10/site-packages/starlette/_exception_handler.py", line 53, in wrapped_app
    raise exc
  File "/home/n8/.local/lib/python3.10/site-packages/starlette/_exception_handler.py", line 42, in wrapped_app
    await app(scope, receive, sender)
  File "/home/n8/.local/lib/python3.10/site-packages/starlette/routing.py", line 715, in __call__
    await self.middleware_stack(scope, receive, send)
  File "/home/n8/.local/lib/python3.10/site-packages/starlette/routing.py", line 735, in app
    await route.handle(scope, receive, send)
  File "/home/n8/.local/lib/python3.10/site-packages/starlette/routing.py", line 288, in handle
    await self.app(scope, receive, send)
  File "/home/n8/.local/lib/python3.10/site-packages/starlette/routing.py", line 76, in app
    await wrap_app_handling_exceptions(app, request)(scope, receive, send)
  File "/home/n8/.local/lib/python3.10/site-packages/starlette/_exception_handler.py", line 53, in wrapped_app
    raise exc
  File "/home/n8/.local/lib/python3.10/site-packages/starlette/_exception_handler.py", line 42, in wrapped_app
    await app(scope, receive, sender)
  File "/home/n8/.local/lib/python3.10/site-packages/starlette/routing.py", line 73, in app
    response = await f(request)
  File "/home/n8/.local/lib/python3.10/site-packages/fastapi/routing.py", line 301, in app
    raw_response = await run_endpoint_function(
  File "/home/n8/.local/lib/python3.10/site-packages/fastapi/routing.py", line 212, in run_endpoint_function
    return await dependant.call(**values)
  File "/home/n8/Documents/capstone/OSUCS461-ExitTicket/OSUCS461/Routers/v1.py", line 30, in write_user
    response = UserLogic.write(user.username, user.time_created)
  File "/home/n8/Documents/capstone/OSUCS461-ExitTicket/OSUCS461/Classes/Database/__init__.py", line 14, in write
    user = WriteUser(username, time_created, uuid)
TypeError: BaseModel.__init__() takes 1 positional argument but 4 were given

2024-12-10 19:09:25,614 - fastAPI - INFO - HP-API - local - Completed request in 0.0165 seconds
2024-12-10 19:09:25,632 - fastAPI - INFO - HP-API - local - Incoming request: PUT http://127.0.0.1:8855/v1/users/1.
2024-12-10 19:09:25,632 - fastAPI - INFO - HP-API - local - Handling function: update_user
2024-12-10 19:09:25,635 - fastAPI - INFO - HP-API - local - Completed request in 0.0022 seconds
2024-12-10 19:09:25,635 - fastAPI - INFO - HP-API - local - Response status code: 422
2024-12-10 19:09:25,650 - fastAPI - INFO - HP-API - local - Incoming request: DELETE http://127.0.0.1:8855/v1/users/1.
2024-12-10 19:09:25,651 - fastAPI - INFO - HP-API - local - Handling function: delete_user
2024-12-10 19:09:25,655 - fastAPI - INFO - HP-API - local - Completed request in 0.0043 seconds
2024-12-10 19:09:25,656 - fastAPI - INFO - HP-API - local - Response status code: 200
2024-12-10 19:09:25,668 - fastAPI - INFO - HP-API - local - Incoming request: GET http://127.0.0.1:8855/v1/posts.
2024-12-10 19:09:25,669 - fastAPI - INFO - HP-API - local - Handling function: unknown
2024-12-10 19:09:25,670 - fastAPI - INFO - HP-API - local - Completed request in 0.0007 seconds
2024-12-10 19:09:25,670 - fastAPI - INFO - HP-API - local - Response status code: 404
2024-12-10 19:09:25,683 - fastAPI - INFO - HP-API - local - Incoming request: GET http://127.0.0.1:8855/v1/posts/1.
2024-12-10 19:09:25,684 - fastAPI - INFO - HP-API - local - Handling function: unknown
2024-12-10 19:09:25,685 - fastAPI - INFO - HP-API - local - Completed request in 0.0009 seconds
2024-12-10 19:09:25,685 - fastAPI - INFO - HP-API - local - Response status code: 404
2024-12-10 19:09:25,698 - fastAPI - INFO - HP-API - local - Incoming request: POST http://127.0.0.1:8855/v1/posts.
2024-12-10 19:09:25,699 - fastAPI - INFO - HP-API - local - Handling function: unknown
2024-12-10 19:09:25,700 - fastAPI - INFO - HP-API - local - Completed request in 0.0007 seconds
2024-12-10 19:09:25,701 - fastAPI - INFO - HP-API - local - Response status code: 404
2024-12-10 19:09:25,713 - fastAPI - INFO - HP-API - local - Incoming request: PUT http://127.0.0.1:8855/v1/posts/1.
2024-12-10 19:09:25,714 - fastAPI - INFO - HP-API - local - Handling function: unknown
2024-12-10 19:09:25,715 - fastAPI - INFO - HP-API - local - Completed request in 0.0006 seconds
2024-12-10 19:09:25,715 - fastAPI - INFO - HP-API - local - Response status code: 404
2024-12-10 19:09:25,728 - fastAPI - INFO - HP-API - local - Incoming request: DELETE http://127.0.0.1:8855/v1/posts/1.
2024-12-10 19:09:25,729 - fastAPI - INFO - HP-API - local - Handling function: unknown
2024-12-10 19:09:25,730 - fastAPI - INFO - HP-API - local - Completed request in 0.0007 seconds
2024-12-10 19:09:25,730 - fastAPI - INFO - HP-API - local - Response status code: 404
2024-12-10 19:09:25,743 - fastAPI - INFO - HP-API - local - Incoming request: GET http://127.0.0.1:8855/v1/users/1/posts.
2024-12-10 19:09:25,744 - fastAPI - INFO - HP-API - local - Handling function: unknown
2024-12-10 19:09:25,745 - fastAPI - INFO - HP-API - local - Completed request in 0.0006 seconds
2024-12-10 19:09:25,745 - fastAPI - INFO - HP-API - local - Response status code: 404
2024-12-10 19:10:08,874 - fastAPI - INFO - HP-API - local - Incoming request: POST http://127.0.0.1:8855/v1/users.
2024-12-10 19:10:08,875 - fastAPI - INFO - HP-API - local - Handling function: write_user
2024-12-10 19:10:08,877 - fastAPI - INFO - HP-API - local - Completed request in 0.0010 seconds
2024-12-10 19:10:08,877 - fastAPI - INFO - HP-API - local - Response status code: 422
2024-12-10 19:11:06,717 - fastAPI - INFO - HP-API - local - Incoming request: POST http://127.0.0.1:8855/v1/users.
2024-12-10 19:11:06,718 - fastAPI - INFO - HP-API - local - Handling function: write_user
2024-12-10 19:11:06,720 - fastAPI - INFO - HP-API - local - Completed request in 0.0017 seconds
2024-12-10 19:11:06,720 - fastAPI - INFO - HP-API - local - Response status code: 422
2024-12-10 19:11:30,610 - fastAPI - INFO - HP-API - local - Incoming request: POST http://127.0.0.1:8855/v1/users.
2024-12-10 19:11:30,611 - fastAPI - INFO - HP-API - local - Handling function: write_user
2024-12-10 19:11:30,613 - fastAPI - INFO - HP-API - local - Completed request in 0.0019 seconds
2024-12-10 19:11:30,613 - fastAPI - INFO - HP-API - local - Response status code: 422
2024-12-10 19:12:03,256 - fastAPI - INFO - HP-API - local - Incoming request: POST http://127.0.0.1:8855/v1/users.
2024-12-10 19:12:03,257 - fastAPI - INFO - HP-API - local - Handling function: write_user
2024-12-10 19:12:03,260 - fastAPI - INFO - HP-API - local - Completed request in 0.0021 seconds
2024-12-10 19:12:03,260 - fastAPI - INFO - HP-API - local - Response status code: 422
2024-12-10 19:13:29,406 - fastAPI - INFO - HP-API - local - Incoming request: POST http://127.0.0.1:8855/v1/users.
2024-12-10 19:13:29,407 - fastAPI - INFO - HP-API - local - Handling function: write_user
2024-12-10 19:13:29,409 - fastAPI - INFO - HP-API - local - Completed request in 0.0011 seconds
2024-12-10 19:13:29,409 - fastAPI - INFO - HP-API - local - Response status code: 422
2024-12-10 19:13:54,471 - fastAPI - INFO - HP-API - local - Incoming request: POST http://127.0.0.1:8855/v1/users.
2024-12-10 19:13:54,471 - fastAPI - INFO - HP-API - local - Handling function: write_user
2024-12-10 19:13:54,472 - fastAPI - INFO - HP-API - local - Completed request in 0.0010 seconds
2024-12-10 19:13:54,472 - fastAPI - INFO - HP-API - local - Response status code: 422
2024-12-10 19:16:43,405 - fastAPI - INFO - HP-API - local - Incoming request: POST http://127.0.0.1:8855/v1/users.
2024-12-10 19:16:43,408 - fastAPI - INFO - HP-API - local - Handling function: write_user
2024-12-10 19:16:43,413 - fastAPI - INFO - HP-API - local - Completed request in 0.0030 seconds
2024-12-10 19:16:43,414 - fastAPI - INFO - HP-API - local - Response status code: 422
2024-12-10 19:21:34,183 - fastAPI - INFO - HP-API - local - Incoming request: POST http://127.0.0.1:8855/v1/users.
2024-12-10 19:21:34,184 - fastAPI - INFO - HP-API - local - Handling function: write_user
2024-12-10 19:21:34,186 - fastAPI - INFO - HP-API - local - Completed request in 0.0017 seconds
2024-12-10 19:21:34,186 - fastAPI - INFO - HP-API - local - Response status code: 422
2024-12-10 19:22:51,886 - fastAPI - INFO - HP-API - local - Incoming request: POST http://127.0.0.1:8855/v1/users.
2024-12-10 19:22:51,887 - fastAPI - INFO - HP-API - local - Handling function: write_user
2024-12-10 19:22:51,889 - fastAPI - INFO - HP-API - local - Completed request in 0.0017 seconds
2024-12-10 19:22:51,889 - fastAPI - INFO - HP-API - local - Response status code: 422
2024-12-10 19:22:56,020 - fastAPI - INFO - HP-API - local - Incoming request: GET http://127.0.0.1:8855/docs.
2024-12-10 19:22:56,022 - fastAPI - INFO - HP-API - local - Handling function: swagger_ui_html
2024-12-10 19:22:56,023 - fastAPI - INFO - HP-API - local - Completed request in 0.0011 seconds
2024-12-10 19:22:56,023 - fastAPI - INFO - HP-API - local - Response status code: 200
2024-12-10 19:22:56,825 - fastAPI - INFO - HP-API - local - Incoming request: GET http://127.0.0.1:8855/openapi.json.
2024-12-10 19:22:56,825 - fastAPI - INFO - HP-API - local - Handling function: openapi
2024-12-10 19:22:56,870 - fastAPI - INFO - HP-API - local - Completed request in 0.0445 seconds
2024-12-10 19:22:56,874 - fastAPI - INFO - HP-API - local - Response status code: 200
2024-12-10 19:23:05,740 - fastAPI - INFO - HP-API - local - Incoming request: POST http://127.0.0.1:8855/v1/users.
2024-12-10 19:23:05,741 - fastAPI - INFO - HP-API - local - Handling function: write_user
2024-12-10 19:23:05,767 - fastAPI - ERROR - HP-API - local - Error processing request. Request was handled by: write_user 
Method: POST - URL: http://127.0.0.1:8855/v1/users - Headers: Headers({'host': '127.0.0.1:8855', 'user-agent': 'Mozilla/5.0 (X11; Linux x86_64; rv:133.0) Gecko/20100101 Firefox/133.0', 'accept': 'application/json', 'accept-language': 'en-US,en;q=0.5', 'accept-encoding': 'gzip, deflate, br, zstd', 'referer': 'http://127.0.0.1:8855/docs', 'content-type': 'application/json', 'content-length': '43', 'origin': 'http://127.0.0.1:8855', 'connection': 'keep-alive', 'sec-fetch-dest': 'empty', 'sec-fetch-mode': 'cors', 'sec-fetch-site': 'same-origin', 'priority': 'u=0'}) 
Stack Trace: 'WriteUser' object has no attribute 'username'
Traceback (most recent call last):
  File "/home/n8/.local/lib/python3.10/site-packages/anyio/streams/memory.py", line 111, in receive
    return self.receive_nowait()
  File "/home/n8/.local/lib/python3.10/site-packages/anyio/streams/memory.py", line 106, in receive_nowait
    raise WouldBlock
anyio.WouldBlock

During handling of the above exception, another exception occurred:

Traceback (most recent call last):
  File "/home/n8/.local/lib/python3.10/site-packages/anyio/streams/memory.py", line 124, in receive
    return receiver.item
AttributeError: 'MemoryObjectItemReceiver' object has no attribute 'item'

During handling of the above exception, another exception occurred:

Traceback (most recent call last):
  File "/home/n8/.local/lib/python3.10/site-packages/starlette/middleware/base.py", line 157, in call_next
    message = await recv_stream.receive()
  File "/home/n8/.local/lib/python3.10/site-packages/anyio/streams/memory.py", line 126, in receive
    raise EndOfStream
anyio.EndOfStream

During handling of the above exception, another exception occurred:

Traceback (most recent call last):
  File "/home/n8/Documents/capstone/OSUCS461-ExitTicket/OSUCS461/main.py", line 32, in dispatch
    response = await call_next(request)
  File "/home/n8/.local/lib/python3.10/site-packages/starlette/middleware/base.py", line 163, in call_next
    raise app_exc
  File "/home/n8/.local/lib/python3.10/site-packages/starlette/middleware/base.py", line 149, in coro
    await self.app(scope, receive_or_disconnect, send_no_error)
  File "/home/n8/.local/lib/python3.10/site-packages/starlette/middleware/exceptions.py", line 62, in __call__
    await wrap_app_handling_exceptions(self.app, conn)(scope, receive, send)
  File "/home/n8/.local/lib/python3.10/site-packages/starlette/_exception_handler.py", line 53, in wrapped_app
    raise exc
  File "/home/n8/.local/lib/python3.10/site-packages/starlette/_exception_handler.py", line 42, in wrapped_app
    await app(scope, receive, sender)
  File "/home/n8/.local/lib/python3.10/site-packages/starlette/routing.py", line 715, in __call__
    await self.middleware_stack(scope, receive, send)
  File "/home/n8/.local/lib/python3.10/site-packages/starlette/routing.py", line 735, in app
    await route.handle(scope, receive, send)
  File "/home/n8/.local/lib/python3.10/site-packages/starlette/routing.py", line 288, in handle
    await self.app(scope, receive, send)
  File "/home/n8/.local/lib/python3.10/site-packages/starlette/routing.py", line 76, in app
    await wrap_app_handling_exceptions(app, request)(scope, receive, send)
  File "/home/n8/.local/lib/python3.10/site-packages/starlette/_exception_handler.py", line 53, in wrapped_app
    raise exc
  File "/home/n8/.local/lib/python3.10/site-packages/starlette/_exception_handler.py", line 42, in wrapped_app
    await app(scope, receive, sender)
  File "/home/n8/.local/lib/python3.10/site-packages/starlette/routing.py", line 73, in app
    response = await f(request)
  File "/home/n8/.local/lib/python3.10/site-packages/fastapi/routing.py", line 301, in app
    raw_response = await run_endpoint_function(
  File "/home/n8/.local/lib/python3.10/site-packages/fastapi/routing.py", line 212, in run_endpoint_function
    return await dependant.call(**values)
  File "/home/n8/Documents/capstone/OSUCS461-ExitTicket/OSUCS461/Routers/v1.py", line 30, in write_user
    response = UserLogic.write(user.username, user.time_created)
  File "/home/n8/.local/lib/python3.10/site-packages/pydantic/main.py", line 856, in __getattr__
    raise AttributeError(f'{type(self).__name__!r} object has no attribute {item!r}')
AttributeError: 'WriteUser' object has no attribute 'username'

2024-12-10 19:23:05,778 - fastAPI - INFO - HP-API - local - Completed request in 0.0341 seconds
2024-12-10 19:26:09,298 - fastAPI - INFO - HP-API - local - Incoming request: POST http://127.0.0.1:8855/v1/users.
2024-12-10 19:26:09,299 - fastAPI - INFO - HP-API - local - Handling function: write_user
2024-12-10 19:26:09,301 - fastAPI - INFO - HP-API - local - Incoming request: GET http://127.0.0.1:8855/docs.
2024-12-10 19:26:09,302 - fastAPI - INFO - HP-API - local - Handling function: swagger_ui_html
2024-12-10 19:26:09,303 - fastAPI - INFO - HP-API - local - Completed request in 0.0010 seconds
2024-12-10 19:26:09,304 - fastAPI - INFO - HP-API - local - Response status code: 200
2024-12-10 19:26:09,326 - fastAPI - ERROR - HP-API - local - Error processing request. Request was handled by: write_user 
Method: POST - URL: http://127.0.0.1:8855/v1/users - Headers: Headers({'host': '127.0.0.1:8855', 'user-agent': 'Mozilla/5.0 (X11; Linux x86_64; rv:133.0) Gecko/20100101 Firefox/133.0', 'accept': 'application/json', 'accept-language': 'en-US,en;q=0.5', 'accept-encoding': 'gzip, deflate, br, zstd', 'referer': 'http://127.0.0.1:8855/docs', 'content-type': 'application/json', 'content-length': '43', 'origin': 'http://127.0.0.1:8855', 'connection': 'keep-alive', 'sec-fetch-dest': 'empty', 'sec-fetch-mode': 'cors', 'sec-fetch-site': 'same-origin', 'priority': 'u=0'}) 
Stack Trace: Object of type AttributeError is not JSON serializable
Traceback (most recent call last):
  File "/home/n8/.local/lib/python3.10/site-packages/anyio/streams/memory.py", line 111, in receive
    return self.receive_nowait()
  File "/home/n8/.local/lib/python3.10/site-packages/anyio/streams/memory.py", line 106, in receive_nowait
    raise WouldBlock
anyio.WouldBlock

During handling of the above exception, another exception occurred:

Traceback (most recent call last):
  File "/home/n8/.local/lib/python3.10/site-packages/anyio/streams/memory.py", line 124, in receive
    return receiver.item
AttributeError: 'MemoryObjectItemReceiver' object has no attribute 'item'

During handling of the above exception, another exception occurred:

Traceback (most recent call last):
  File "/home/n8/.local/lib/python3.10/site-packages/starlette/middleware/base.py", line 157, in call_next
    message = await recv_stream.receive()
  File "/home/n8/.local/lib/python3.10/site-packages/anyio/streams/memory.py", line 126, in receive
    raise EndOfStream
anyio.EndOfStream

During handling of the above exception, another exception occurred:

Traceback (most recent call last):
  File "/home/n8/Documents/capstone/OSUCS461-ExitTicket/OSUCS461/main.py", line 32, in dispatch
    response = await call_next(request)
  File "/home/n8/.local/lib/python3.10/site-packages/starlette/middleware/base.py", line 163, in call_next
    raise app_exc
  File "/home/n8/.local/lib/python3.10/site-packages/starlette/middleware/base.py", line 149, in coro
    await self.app(scope, receive_or_disconnect, send_no_error)
  File "/home/n8/.local/lib/python3.10/site-packages/starlette/middleware/exceptions.py", line 62, in __call__
    await wrap_app_handling_exceptions(self.app, conn)(scope, receive, send)
  File "/home/n8/.local/lib/python3.10/site-packages/starlette/_exception_handler.py", line 53, in wrapped_app
    raise exc
  File "/home/n8/.local/lib/python3.10/site-packages/starlette/_exception_handler.py", line 42, in wrapped_app
    await app(scope, receive, sender)
  File "/home/n8/.local/lib/python3.10/site-packages/starlette/routing.py", line 715, in __call__
    await self.middleware_stack(scope, receive, send)
  File "/home/n8/.local/lib/python3.10/site-packages/starlette/routing.py", line 735, in app
    await route.handle(scope, receive, send)
  File "/home/n8/.local/lib/python3.10/site-packages/starlette/routing.py", line 288, in handle
    await self.app(scope, receive, send)
  File "/home/n8/.local/lib/python3.10/site-packages/starlette/routing.py", line 76, in app
    await wrap_app_handling_exceptions(app, request)(scope, receive, send)
  File "/home/n8/.local/lib/python3.10/site-packages/starlette/_exception_handler.py", line 59, in wrapped_app
    response = await handler(conn, exc)
  File "/home/n8/.local/lib/python3.10/site-packages/fastapi/exception_handlers.py", line 15, in http_exception_handler
    return JSONResponse(
  File "/home/n8/.local/lib/python3.10/site-packages/starlette/responses.py", line 180, in __init__
    super().__init__(content, status_code, headers, media_type, background)
  File "/home/n8/.local/lib/python3.10/site-packages/starlette/responses.py", line 43, in __init__
    self.body = self.render(content)
  File "/home/n8/.local/lib/python3.10/site-packages/starlette/responses.py", line 183, in render
    return json.dumps(
  File "/usr/lib/python3.10/json/__init__.py", line 238, in dumps
    **kw).encode(obj)
  File "/usr/lib/python3.10/json/encoder.py", line 199, in encode
    chunks = self.iterencode(o, _one_shot=True)
  File "/usr/lib/python3.10/json/encoder.py", line 257, in iterencode
    return _iterencode(o, 0)
  File "/usr/lib/python3.10/json/encoder.py", line 179, in default
    raise TypeError(f'Object of type {o.__class__.__name__} '
TypeError: Object of type AttributeError is not JSON serializable

2024-12-10 19:26:09,329 - fastAPI - INFO - HP-API - local - Completed request in 0.0293 seconds
2024-12-10 19:26:10,157 - fastAPI - INFO - HP-API - local - Incoming request: GET http://127.0.0.1:8855/openapi.json.
2024-12-10 19:26:10,157 - fastAPI - INFO - HP-API - local - Handling function: openapi
2024-12-10 19:26:10,215 - fastAPI - INFO - HP-API - local - Completed request in 0.0543 seconds
2024-12-10 19:26:10,216 - fastAPI - INFO - HP-API - local - Response status code: 200
2024-12-10 19:26:15,894 - fastAPI - INFO - HP-API - local - Incoming request: POST http://127.0.0.1:8855/v1/users.
2024-12-10 19:26:15,894 - fastAPI - INFO - HP-API - local - Handling function: write_user
2024-12-10 19:26:15,899 - fastAPI - ERROR - HP-API - local - Error processing request. Request was handled by: write_user 
Method: POST - URL: http://127.0.0.1:8855/v1/users - Headers: Headers({'host': '127.0.0.1:8855', 'user-agent': 'Mozilla/5.0 (X11; Linux x86_64; rv:133.0) Gecko/20100101 Firefox/133.0', 'accept': 'application/json', 'accept-language': 'en-US,en;q=0.5', 'accept-encoding': 'gzip, deflate, br, zstd', 'referer': 'http://127.0.0.1:8855/docs', 'content-type': 'application/json', 'content-length': '43', 'origin': 'http://127.0.0.1:8855', 'connection': 'keep-alive', 'sec-fetch-dest': 'empty', 'sec-fetch-mode': 'cors', 'sec-fetch-site': 'same-origin', 'priority': 'u=0'}) 
Stack Trace: Object of type AttributeError is not JSON serializable
Traceback (most recent call last):
  File "/home/n8/.local/lib/python3.10/site-packages/anyio/streams/memory.py", line 111, in receive
    return self.receive_nowait()
  File "/home/n8/.local/lib/python3.10/site-packages/anyio/streams/memory.py", line 106, in receive_nowait
    raise WouldBlock
anyio.WouldBlock

During handling of the above exception, another exception occurred:

Traceback (most recent call last):
  File "/home/n8/.local/lib/python3.10/site-packages/anyio/streams/memory.py", line 124, in receive
    return receiver.item
AttributeError: 'MemoryObjectItemReceiver' object has no attribute 'item'

During handling of the above exception, another exception occurred:

Traceback (most recent call last):
  File "/home/n8/.local/lib/python3.10/site-packages/starlette/middleware/base.py", line 157, in call_next
    message = await recv_stream.receive()
  File "/home/n8/.local/lib/python3.10/site-packages/anyio/streams/memory.py", line 126, in receive
    raise EndOfStream
anyio.EndOfStream

During handling of the above exception, another exception occurred:

Traceback (most recent call last):
  File "/home/n8/Documents/capstone/OSUCS461-ExitTicket/OSUCS461/main.py", line 32, in dispatch
    response = await call_next(request)
  File "/home/n8/.local/lib/python3.10/site-packages/starlette/middleware/base.py", line 163, in call_next
    raise app_exc
  File "/home/n8/.local/lib/python3.10/site-packages/starlette/middleware/base.py", line 149, in coro
    await self.app(scope, receive_or_disconnect, send_no_error)
  File "/home/n8/.local/lib/python3.10/site-packages/starlette/middleware/exceptions.py", line 62, in __call__
    await wrap_app_handling_exceptions(self.app, conn)(scope, receive, send)
  File "/home/n8/.local/lib/python3.10/site-packages/starlette/_exception_handler.py", line 53, in wrapped_app
    raise exc
  File "/home/n8/.local/lib/python3.10/site-packages/starlette/_exception_handler.py", line 42, in wrapped_app
    await app(scope, receive, sender)
  File "/home/n8/.local/lib/python3.10/site-packages/starlette/routing.py", line 715, in __call__
    await self.middleware_stack(scope, receive, send)
  File "/home/n8/.local/lib/python3.10/site-packages/starlette/routing.py", line 735, in app
    await route.handle(scope, receive, send)
  File "/home/n8/.local/lib/python3.10/site-packages/starlette/routing.py", line 288, in handle
    await self.app(scope, receive, send)
  File "/home/n8/.local/lib/python3.10/site-packages/starlette/routing.py", line 76, in app
    await wrap_app_handling_exceptions(app, request)(scope, receive, send)
  File "/home/n8/.local/lib/python3.10/site-packages/starlette/_exception_handler.py", line 59, in wrapped_app
    response = await handler(conn, exc)
  File "/home/n8/.local/lib/python3.10/site-packages/fastapi/exception_handlers.py", line 15, in http_exception_handler
    return JSONResponse(
  File "/home/n8/.local/lib/python3.10/site-packages/starlette/responses.py", line 180, in __init__
    super().__init__(content, status_code, headers, media_type, background)
  File "/home/n8/.local/lib/python3.10/site-packages/starlette/responses.py", line 43, in __init__
    self.body = self.render(content)
  File "/home/n8/.local/lib/python3.10/site-packages/starlette/responses.py", line 183, in render
    return json.dumps(
  File "/usr/lib/python3.10/json/__init__.py", line 238, in dumps
    **kw).encode(obj)
  File "/usr/lib/python3.10/json/encoder.py", line 199, in encode
    chunks = self.iterencode(o, _one_shot=True)
  File "/usr/lib/python3.10/json/encoder.py", line 257, in iterencode
    return _iterencode(o, 0)
  File "/usr/lib/python3.10/json/encoder.py", line 179, in default
    raise TypeError(f'Object of type {o.__class__.__name__} '
TypeError: Object of type AttributeError is not JSON serializable

2024-12-10 19:26:15,900 - fastAPI - INFO - HP-API - local - Completed request in 0.0050 seconds
2024-12-10 19:26:42,557 - fastAPI - INFO - HP-API - local - Incoming request: POST http://127.0.0.1:8855/v1/users.
2024-12-10 19:26:42,558 - fastAPI - INFO - HP-API - local - Handling function: write_user
2024-12-10 19:26:42,568 - fastAPI - ERROR - HP-API - local - Error processing request. Request was handled by: write_user 
Method: POST - URL: http://127.0.0.1:8855/v1/users - Headers: Headers({'host': '127.0.0.1:8855', 'user-agent': 'Mozilla/5.0 (X11; Linux x86_64; rv:133.0) Gecko/20100101 Firefox/133.0', 'accept': 'application/json', 'accept-language': 'en-US,en;q=0.5', 'accept-encoding': 'gzip, deflate, br, zstd', 'referer': 'http://127.0.0.1:8855/docs', 'content-type': 'application/json', 'content-length': '43', 'origin': 'http://127.0.0.1:8855', 'connection': 'keep-alive', 'sec-fetch-dest': 'empty', 'sec-fetch-mode': 'cors', 'sec-fetch-site': 'same-origin', 'priority': 'u=0'}) 
Stack Trace: Object of type AttributeError is not JSON serializable
Traceback (most recent call last):
  File "/home/n8/.local/lib/python3.10/site-packages/anyio/streams/memory.py", line 111, in receive
    return self.receive_nowait()
  File "/home/n8/.local/lib/python3.10/site-packages/anyio/streams/memory.py", line 106, in receive_nowait
    raise WouldBlock
anyio.WouldBlock

During handling of the above exception, another exception occurred:

Traceback (most recent call last):
  File "/home/n8/.local/lib/python3.10/site-packages/anyio/streams/memory.py", line 124, in receive
    return receiver.item
AttributeError: 'MemoryObjectItemReceiver' object has no attribute 'item'

During handling of the above exception, another exception occurred:

Traceback (most recent call last):
  File "/home/n8/.local/lib/python3.10/site-packages/starlette/middleware/base.py", line 157, in call_next
    message = await recv_stream.receive()
  File "/home/n8/.local/lib/python3.10/site-packages/anyio/streams/memory.py", line 126, in receive
    raise EndOfStream
anyio.EndOfStream

During handling of the above exception, another exception occurred:

Traceback (most recent call last):
  File "/home/n8/Documents/capstone/OSUCS461-ExitTicket/OSUCS461/main.py", line 32, in dispatch
    response = await call_next(request)
  File "/home/n8/.local/lib/python3.10/site-packages/starlette/middleware/base.py", line 163, in call_next
    raise app_exc
  File "/home/n8/.local/lib/python3.10/site-packages/starlette/middleware/base.py", line 149, in coro
    await self.app(scope, receive_or_disconnect, send_no_error)
  File "/home/n8/.local/lib/python3.10/site-packages/starlette/middleware/exceptions.py", line 62, in __call__
    await wrap_app_handling_exceptions(self.app, conn)(scope, receive, send)
  File "/home/n8/.local/lib/python3.10/site-packages/starlette/_exception_handler.py", line 53, in wrapped_app
    raise exc
  File "/home/n8/.local/lib/python3.10/site-packages/starlette/_exception_handler.py", line 42, in wrapped_app
    await app(scope, receive, sender)
  File "/home/n8/.local/lib/python3.10/site-packages/starlette/routing.py", line 715, in __call__
    await self.middleware_stack(scope, receive, send)
  File "/home/n8/.local/lib/python3.10/site-packages/starlette/routing.py", line 735, in app
    await route.handle(scope, receive, send)
  File "/home/n8/.local/lib/python3.10/site-packages/starlette/routing.py", line 288, in handle
    await self.app(scope, receive, send)
  File "/home/n8/.local/lib/python3.10/site-packages/starlette/routing.py", line 76, in app
    await wrap_app_handling_exceptions(app, request)(scope, receive, send)
  File "/home/n8/.local/lib/python3.10/site-packages/starlette/_exception_handler.py", line 59, in wrapped_app
    response = await handler(conn, exc)
  File "/home/n8/.local/lib/python3.10/site-packages/fastapi/exception_handlers.py", line 15, in http_exception_handler
    return JSONResponse(
  File "/home/n8/.local/lib/python3.10/site-packages/starlette/responses.py", line 180, in __init__
    super().__init__(content, status_code, headers, media_type, background)
  File "/home/n8/.local/lib/python3.10/site-packages/starlette/responses.py", line 43, in __init__
    self.body = self.render(content)
  File "/home/n8/.local/lib/python3.10/site-packages/starlette/responses.py", line 183, in render
    return json.dumps(
  File "/usr/lib/python3.10/json/__init__.py", line 238, in dumps
    **kw).encode(obj)
  File "/usr/lib/python3.10/json/encoder.py", line 199, in encode
    chunks = self.iterencode(o, _one_shot=True)
  File "/usr/lib/python3.10/json/encoder.py", line 257, in iterencode
    return _iterencode(o, 0)
  File "/usr/lib/python3.10/json/encoder.py", line 179, in default
    raise TypeError(f'Object of type {o.__class__.__name__} '
TypeError: Object of type AttributeError is not JSON serializable

2024-12-10 19:26:42,569 - fastAPI - INFO - HP-API - local - Completed request in 0.0111 seconds
2024-12-10 19:26:43,816 - fastAPI - INFO - HP-API - local - Incoming request: POST http://127.0.0.1:8855/v1/users.
2024-12-10 19:26:43,818 - fastAPI - INFO - HP-API - local - Handling function: write_user
2024-12-10 19:26:43,822 - fastAPI - ERROR - HP-API - local - Error processing request. Request was handled by: write_user 
Method: POST - URL: http://127.0.0.1:8855/v1/users - Headers: Headers({'host': '127.0.0.1:8855', 'user-agent': 'Mozilla/5.0 (X11; Linux x86_64; rv:133.0) Gecko/20100101 Firefox/133.0', 'accept': 'application/json', 'accept-language': 'en-US,en;q=0.5', 'accept-encoding': 'gzip, deflate, br, zstd', 'referer': 'http://127.0.0.1:8855/docs', 'content-type': 'application/json', 'content-length': '43', 'origin': 'http://127.0.0.1:8855', 'connection': 'keep-alive', 'sec-fetch-dest': 'empty', 'sec-fetch-mode': 'cors', 'sec-fetch-site': 'same-origin', 'priority': 'u=0'}) 
Stack Trace: Object of type AttributeError is not JSON serializable
Traceback (most recent call last):
  File "/home/n8/.local/lib/python3.10/site-packages/anyio/streams/memory.py", line 111, in receive
    return self.receive_nowait()
  File "/home/n8/.local/lib/python3.10/site-packages/anyio/streams/memory.py", line 106, in receive_nowait
    raise WouldBlock
anyio.WouldBlock

During handling of the above exception, another exception occurred:

Traceback (most recent call last):
  File "/home/n8/.local/lib/python3.10/site-packages/anyio/streams/memory.py", line 124, in receive
    return receiver.item
AttributeError: 'MemoryObjectItemReceiver' object has no attribute 'item'

During handling of the above exception, another exception occurred:

Traceback (most recent call last):
  File "/home/n8/.local/lib/python3.10/site-packages/starlette/middleware/base.py", line 157, in call_next
    message = await recv_stream.receive()
  File "/home/n8/.local/lib/python3.10/site-packages/anyio/streams/memory.py", line 126, in receive
    raise EndOfStream
anyio.EndOfStream

During handling of the above exception, another exception occurred:

Traceback (most recent call last):
  File "/home/n8/Documents/capstone/OSUCS461-ExitTicket/OSUCS461/main.py", line 32, in dispatch
    response = await call_next(request)
  File "/home/n8/.local/lib/python3.10/site-packages/starlette/middleware/base.py", line 163, in call_next
    raise app_exc
  File "/home/n8/.local/lib/python3.10/site-packages/starlette/middleware/base.py", line 149, in coro
    await self.app(scope, receive_or_disconnect, send_no_error)
  File "/home/n8/.local/lib/python3.10/site-packages/starlette/middleware/exceptions.py", line 62, in __call__
    await wrap_app_handling_exceptions(self.app, conn)(scope, receive, send)
  File "/home/n8/.local/lib/python3.10/site-packages/starlette/_exception_handler.py", line 53, in wrapped_app
    raise exc
  File "/home/n8/.local/lib/python3.10/site-packages/starlette/_exception_handler.py", line 42, in wrapped_app
    await app(scope, receive, sender)
  File "/home/n8/.local/lib/python3.10/site-packages/starlette/routing.py", line 715, in __call__
    await self.middleware_stack(scope, receive, send)
  File "/home/n8/.local/lib/python3.10/site-packages/starlette/routing.py", line 735, in app
    await route.handle(scope, receive, send)
  File "/home/n8/.local/lib/python3.10/site-packages/starlette/routing.py", line 288, in handle
    await self.app(scope, receive, send)
  File "/home/n8/.local/lib/python3.10/site-packages/starlette/routing.py", line 76, in app
    await wrap_app_handling_exceptions(app, request)(scope, receive, send)
  File "/home/n8/.local/lib/python3.10/site-packages/starlette/_exception_handler.py", line 59, in wrapped_app
    response = await handler(conn, exc)
  File "/home/n8/.local/lib/python3.10/site-packages/fastapi/exception_handlers.py", line 15, in http_exception_handler
    return JSONResponse(
  File "/home/n8/.local/lib/python3.10/site-packages/starlette/responses.py", line 180, in __init__
    super().__init__(content, status_code, headers, media_type, background)
  File "/home/n8/.local/lib/python3.10/site-packages/starlette/responses.py", line 43, in __init__
    self.body = self.render(content)
  File "/home/n8/.local/lib/python3.10/site-packages/starlette/responses.py", line 183, in render
    return json.dumps(
  File "/usr/lib/python3.10/json/__init__.py", line 238, in dumps
    **kw).encode(obj)
  File "/usr/lib/python3.10/json/encoder.py", line 199, in encode
    chunks = self.iterencode(o, _one_shot=True)
  File "/usr/lib/python3.10/json/encoder.py", line 257, in iterencode
    return _iterencode(o, 0)
  File "/usr/lib/python3.10/json/encoder.py", line 179, in default
    raise TypeError(f'Object of type {o.__class__.__name__} '
TypeError: Object of type AttributeError is not JSON serializable

2024-12-10 19:26:43,840 - fastAPI - INFO - HP-API - local - Completed request in 0.0207 seconds
2024-12-10 19:26:44,622 - fastAPI - INFO - HP-API - local - Incoming request: POST http://127.0.0.1:8855/v1/users.
2024-12-10 19:26:44,623 - fastAPI - INFO - HP-API - local - Handling function: write_user
2024-12-10 19:26:44,631 - fastAPI - ERROR - HP-API - local - Error processing request. Request was handled by: write_user 
Method: POST - URL: http://127.0.0.1:8855/v1/users - Headers: Headers({'host': '127.0.0.1:8855', 'user-agent': 'Mozilla/5.0 (X11; Linux x86_64; rv:133.0) Gecko/20100101 Firefox/133.0', 'accept': 'application/json', 'accept-language': 'en-US,en;q=0.5', 'accept-encoding': 'gzip, deflate, br, zstd', 'referer': 'http://127.0.0.1:8855/docs', 'content-type': 'application/json', 'content-length': '43', 'origin': 'http://127.0.0.1:8855', 'connection': 'keep-alive', 'sec-fetch-dest': 'empty', 'sec-fetch-mode': 'cors', 'sec-fetch-site': 'same-origin', 'priority': 'u=0'}) 
Stack Trace: Object of type AttributeError is not JSON serializable
Traceback (most recent call last):
  File "/home/n8/.local/lib/python3.10/site-packages/anyio/streams/memory.py", line 111, in receive
    return self.receive_nowait()
  File "/home/n8/.local/lib/python3.10/site-packages/anyio/streams/memory.py", line 106, in receive_nowait
    raise WouldBlock
anyio.WouldBlock

During handling of the above exception, another exception occurred:

Traceback (most recent call last):
  File "/home/n8/.local/lib/python3.10/site-packages/anyio/streams/memory.py", line 124, in receive
    return receiver.item
AttributeError: 'MemoryObjectItemReceiver' object has no attribute 'item'

During handling of the above exception, another exception occurred:

Traceback (most recent call last):
  File "/home/n8/.local/lib/python3.10/site-packages/starlette/middleware/base.py", line 157, in call_next
    message = await recv_stream.receive()
  File "/home/n8/.local/lib/python3.10/site-packages/anyio/streams/memory.py", line 126, in receive
    raise EndOfStream
anyio.EndOfStream

During handling of the above exception, another exception occurred:

Traceback (most recent call last):
  File "/home/n8/Documents/capstone/OSUCS461-ExitTicket/OSUCS461/main.py", line 32, in dispatch
    response = await call_next(request)
  File "/home/n8/.local/lib/python3.10/site-packages/starlette/middleware/base.py", line 163, in call_next
    raise app_exc
  File "/home/n8/.local/lib/python3.10/site-packages/starlette/middleware/base.py", line 149, in coro
    await self.app(scope, receive_or_disconnect, send_no_error)
  File "/home/n8/.local/lib/python3.10/site-packages/starlette/middleware/exceptions.py", line 62, in __call__
    await wrap_app_handling_exceptions(self.app, conn)(scope, receive, send)
  File "/home/n8/.local/lib/python3.10/site-packages/starlette/_exception_handler.py", line 53, in wrapped_app
    raise exc
  File "/home/n8/.local/lib/python3.10/site-packages/starlette/_exception_handler.py", line 42, in wrapped_app
    await app(scope, receive, sender)
  File "/home/n8/.local/lib/python3.10/site-packages/starlette/routing.py", line 715, in __call__
    await self.middleware_stack(scope, receive, send)
  File "/home/n8/.local/lib/python3.10/site-packages/starlette/routing.py", line 735, in app
    await route.handle(scope, receive, send)
  File "/home/n8/.local/lib/python3.10/site-packages/starlette/routing.py", line 288, in handle
    await self.app(scope, receive, send)
  File "/home/n8/.local/lib/python3.10/site-packages/starlette/routing.py", line 76, in app
    await wrap_app_handling_exceptions(app, request)(scope, receive, send)
  File "/home/n8/.local/lib/python3.10/site-packages/starlette/_exception_handler.py", line 59, in wrapped_app
    response = await handler(conn, exc)
  File "/home/n8/.local/lib/python3.10/site-packages/fastapi/exception_handlers.py", line 15, in http_exception_handler
    return JSONResponse(
  File "/home/n8/.local/lib/python3.10/site-packages/starlette/responses.py", line 180, in __init__
    super().__init__(content, status_code, headers, media_type, background)
  File "/home/n8/.local/lib/python3.10/site-packages/starlette/responses.py", line 43, in __init__
    self.body = self.render(content)
  File "/home/n8/.local/lib/python3.10/site-packages/starlette/responses.py", line 183, in render
    return json.dumps(
  File "/usr/lib/python3.10/json/__init__.py", line 238, in dumps
    **kw).encode(obj)
  File "/usr/lib/python3.10/json/encoder.py", line 199, in encode
    chunks = self.iterencode(o, _one_shot=True)
  File "/usr/lib/python3.10/json/encoder.py", line 257, in iterencode
    return _iterencode(o, 0)
  File "/usr/lib/python3.10/json/encoder.py", line 179, in default
    raise TypeError(f'Object of type {o.__class__.__name__} '
TypeError: Object of type AttributeError is not JSON serializable

2024-12-10 19:26:44,638 - fastAPI - INFO - HP-API - local - Completed request in 0.0146 seconds
2024-12-10 19:26:46,434 - fastAPI - INFO - HP-API - local - Incoming request: POST http://127.0.0.1:8855/v1/users.
2024-12-10 19:26:46,434 - fastAPI - INFO - HP-API - local - Handling function: write_user
2024-12-10 19:26:46,441 - fastAPI - ERROR - HP-API - local - Error processing request. Request was handled by: write_user 
Method: POST - URL: http://127.0.0.1:8855/v1/users - Headers: Headers({'host': '127.0.0.1:8855', 'user-agent': 'Mozilla/5.0 (X11; Linux x86_64; rv:133.0) Gecko/20100101 Firefox/133.0', 'accept': 'application/json', 'accept-language': 'en-US,en;q=0.5', 'accept-encoding': 'gzip, deflate, br, zstd', 'referer': 'http://127.0.0.1:8855/docs', 'content-type': 'application/json', 'content-length': '43', 'origin': 'http://127.0.0.1:8855', 'connection': 'keep-alive', 'sec-fetch-dest': 'empty', 'sec-fetch-mode': 'cors', 'sec-fetch-site': 'same-origin', 'priority': 'u=0'}) 
Stack Trace: Object of type AttributeError is not JSON serializable
Traceback (most recent call last):
  File "/home/n8/.local/lib/python3.10/site-packages/anyio/streams/memory.py", line 111, in receive
    return self.receive_nowait()
  File "/home/n8/.local/lib/python3.10/site-packages/anyio/streams/memory.py", line 106, in receive_nowait
    raise WouldBlock
anyio.WouldBlock

During handling of the above exception, another exception occurred:

Traceback (most recent call last):
  File "/home/n8/.local/lib/python3.10/site-packages/anyio/streams/memory.py", line 124, in receive
    return receiver.item
AttributeError: 'MemoryObjectItemReceiver' object has no attribute 'item'

During handling of the above exception, another exception occurred:

Traceback (most recent call last):
  File "/home/n8/.local/lib/python3.10/site-packages/starlette/middleware/base.py", line 157, in call_next
    message = await recv_stream.receive()
  File "/home/n8/.local/lib/python3.10/site-packages/anyio/streams/memory.py", line 126, in receive
    raise EndOfStream
anyio.EndOfStream

During handling of the above exception, another exception occurred:

Traceback (most recent call last):
  File "/home/n8/Documents/capstone/OSUCS461-ExitTicket/OSUCS461/main.py", line 32, in dispatch
    response = await call_next(request)
  File "/home/n8/.local/lib/python3.10/site-packages/starlette/middleware/base.py", line 163, in call_next
    raise app_exc
  File "/home/n8/.local/lib/python3.10/site-packages/starlette/middleware/base.py", line 149, in coro
    await self.app(scope, receive_or_disconnect, send_no_error)
  File "/home/n8/.local/lib/python3.10/site-packages/starlette/middleware/exceptions.py", line 62, in __call__
    await wrap_app_handling_exceptions(self.app, conn)(scope, receive, send)
  File "/home/n8/.local/lib/python3.10/site-packages/starlette/_exception_handler.py", line 53, in wrapped_app
    raise exc
  File "/home/n8/.local/lib/python3.10/site-packages/starlette/_exception_handler.py", line 42, in wrapped_app
    await app(scope, receive, sender)
  File "/home/n8/.local/lib/python3.10/site-packages/starlette/routing.py", line 715, in __call__
    await self.middleware_stack(scope, receive, send)
  File "/home/n8/.local/lib/python3.10/site-packages/starlette/routing.py", line 735, in app
    await route.handle(scope, receive, send)
  File "/home/n8/.local/lib/python3.10/site-packages/starlette/routing.py", line 288, in handle
    await self.app(scope, receive, send)
  File "/home/n8/.local/lib/python3.10/site-packages/starlette/routing.py", line 76, in app
    await wrap_app_handling_exceptions(app, request)(scope, receive, send)
  File "/home/n8/.local/lib/python3.10/site-packages/starlette/_exception_handler.py", line 59, in wrapped_app
    response = await handler(conn, exc)
  File "/home/n8/.local/lib/python3.10/site-packages/fastapi/exception_handlers.py", line 15, in http_exception_handler
    return JSONResponse(
  File "/home/n8/.local/lib/python3.10/site-packages/starlette/responses.py", line 180, in __init__
    super().__init__(content, status_code, headers, media_type, background)
  File "/home/n8/.local/lib/python3.10/site-packages/starlette/responses.py", line 43, in __init__
    self.body = self.render(content)
  File "/home/n8/.local/lib/python3.10/site-packages/starlette/responses.py", line 183, in render
    return json.dumps(
  File "/usr/lib/python3.10/json/__init__.py", line 238, in dumps
    **kw).encode(obj)
  File "/usr/lib/python3.10/json/encoder.py", line 199, in encode
    chunks = self.iterencode(o, _one_shot=True)
  File "/usr/lib/python3.10/json/encoder.py", line 257, in iterencode
    return _iterencode(o, 0)
  File "/usr/lib/python3.10/json/encoder.py", line 179, in default
    raise TypeError(f'Object of type {o.__class__.__name__} '
TypeError: Object of type AttributeError is not JSON serializable

2024-12-10 19:26:46,443 - fastAPI - INFO - HP-API - local - Completed request in 0.0081 seconds
2024-12-10 19:26:47,921 - fastAPI - INFO - HP-API - local - Incoming request: POST http://127.0.0.1:8855/v1/users.
2024-12-10 19:26:47,922 - fastAPI - INFO - HP-API - local - Handling function: write_user
2024-12-10 19:26:47,927 - fastAPI - ERROR - HP-API - local - Error processing request. Request was handled by: write_user 
Method: POST - URL: http://127.0.0.1:8855/v1/users - Headers: Headers({'host': '127.0.0.1:8855', 'user-agent': 'Mozilla/5.0 (X11; Linux x86_64; rv:133.0) Gecko/20100101 Firefox/133.0', 'accept': 'application/json', 'accept-language': 'en-US,en;q=0.5', 'accept-encoding': 'gzip, deflate, br, zstd', 'referer': 'http://127.0.0.1:8855/docs', 'content-type': 'application/json', 'content-length': '43', 'origin': 'http://127.0.0.1:8855', 'connection': 'keep-alive', 'sec-fetch-dest': 'empty', 'sec-fetch-mode': 'cors', 'sec-fetch-site': 'same-origin', 'priority': 'u=0'}) 
Stack Trace: Object of type AttributeError is not JSON serializable
Traceback (most recent call last):
  File "/home/n8/.local/lib/python3.10/site-packages/anyio/streams/memory.py", line 111, in receive
    return self.receive_nowait()
  File "/home/n8/.local/lib/python3.10/site-packages/anyio/streams/memory.py", line 106, in receive_nowait
    raise WouldBlock
anyio.WouldBlock

During handling of the above exception, another exception occurred:

Traceback (most recent call last):
  File "/home/n8/.local/lib/python3.10/site-packages/anyio/streams/memory.py", line 124, in receive
    return receiver.item
AttributeError: 'MemoryObjectItemReceiver' object has no attribute 'item'

During handling of the above exception, another exception occurred:

Traceback (most recent call last):
  File "/home/n8/.local/lib/python3.10/site-packages/starlette/middleware/base.py", line 157, in call_next
    message = await recv_stream.receive()
  File "/home/n8/.local/lib/python3.10/site-packages/anyio/streams/memory.py", line 126, in receive
    raise EndOfStream
anyio.EndOfStream

During handling of the above exception, another exception occurred:

Traceback (most recent call last):
  File "/home/n8/Documents/capstone/OSUCS461-ExitTicket/OSUCS461/main.py", line 32, in dispatch
    response = await call_next(request)
  File "/home/n8/.local/lib/python3.10/site-packages/starlette/middleware/base.py", line 163, in call_next
    raise app_exc
  File "/home/n8/.local/lib/python3.10/site-packages/starlette/middleware/base.py", line 149, in coro
    await self.app(scope, receive_or_disconnect, send_no_error)
  File "/home/n8/.local/lib/python3.10/site-packages/starlette/middleware/exceptions.py", line 62, in __call__
    await wrap_app_handling_exceptions(self.app, conn)(scope, receive, send)
  File "/home/n8/.local/lib/python3.10/site-packages/starlette/_exception_handler.py", line 53, in wrapped_app
    raise exc
  File "/home/n8/.local/lib/python3.10/site-packages/starlette/_exception_handler.py", line 42, in wrapped_app
    await app(scope, receive, sender)
  File "/home/n8/.local/lib/python3.10/site-packages/starlette/routing.py", line 715, in __call__
    await self.middleware_stack(scope, receive, send)
  File "/home/n8/.local/lib/python3.10/site-packages/starlette/routing.py", line 735, in app
    await route.handle(scope, receive, send)
  File "/home/n8/.local/lib/python3.10/site-packages/starlette/routing.py", line 288, in handle
    await self.app(scope, receive, send)
  File "/home/n8/.local/lib/python3.10/site-packages/starlette/routing.py", line 76, in app
    await wrap_app_handling_exceptions(app, request)(scope, receive, send)
  File "/home/n8/.local/lib/python3.10/site-packages/starlette/_exception_handler.py", line 59, in wrapped_app
    response = await handler(conn, exc)
  File "/home/n8/.local/lib/python3.10/site-packages/fastapi/exception_handlers.py", line 15, in http_exception_handler
    return JSONResponse(
  File "/home/n8/.local/lib/python3.10/site-packages/starlette/responses.py", line 180, in __init__
    super().__init__(content, status_code, headers, media_type, background)
  File "/home/n8/.local/lib/python3.10/site-packages/starlette/responses.py", line 43, in __init__
    self.body = self.render(content)
  File "/home/n8/.local/lib/python3.10/site-packages/starlette/responses.py", line 183, in render
    return json.dumps(
  File "/usr/lib/python3.10/json/__init__.py", line 238, in dumps
    **kw).encode(obj)
  File "/usr/lib/python3.10/json/encoder.py", line 199, in encode
    chunks = self.iterencode(o, _one_shot=True)
  File "/usr/lib/python3.10/json/encoder.py", line 257, in iterencode
    return _iterencode(o, 0)
  File "/usr/lib/python3.10/json/encoder.py", line 179, in default
    raise TypeError(f'Object of type {o.__class__.__name__} '
TypeError: Object of type AttributeError is not JSON serializable

2024-12-10 19:26:47,931 - fastAPI - INFO - HP-API - local - Completed request in 0.0094 seconds
2024-12-10 19:27:51,447 - fastAPI - INFO - HP-API - local - Incoming request: POST http://127.0.0.1:8855/v1/users.
2024-12-10 19:27:51,447 - fastAPI - INFO - HP-API - local - Handling function: write_user
2024-12-10 19:27:51,448 - fastAPI - INFO - HP-API - local - Completed request in 0.0010 seconds
2024-12-10 19:27:51,448 - fastAPI - INFO - HP-API - local - Response status code: 422
2024-12-10 19:28:44,432 - fastAPI - INFO - HP-API - local - Incoming request: POST http://127.0.0.1:8855/v1/users.
2024-12-10 19:28:44,433 - fastAPI - INFO - HP-API - local - Handling function: write_user
2024-12-10 19:28:44,436 - fastAPI - ERROR - HP-API - local - Error processing request. Request was handled by: write_user 
Method: POST - URL: http://127.0.0.1:8855/v1/users - Headers: Headers({'host': '127.0.0.1:8855', 'user-agent': 'Mozilla/5.0 (X11; Linux x86_64; rv:133.0) Gecko/20100101 Firefox/133.0', 'accept': 'application/json', 'accept-language': 'en-US,en;q=0.5', 'accept-encoding': 'gzip, deflate, br, zstd', 'referer': 'http://127.0.0.1:8855/docs', 'content-type': 'application/json', 'content-length': '43', 'origin': 'http://127.0.0.1:8855', 'connection': 'keep-alive', 'sec-fetch-dest': 'empty', 'sec-fetch-mode': 'cors', 'sec-fetch-site': 'same-origin', 'priority': 'u=0'}) 
Stack Trace: Object of type AttributeError is not JSON serializable
Traceback (most recent call last):
  File "/home/n8/.local/lib/python3.10/site-packages/anyio/streams/memory.py", line 111, in receive
    return self.receive_nowait()
  File "/home/n8/.local/lib/python3.10/site-packages/anyio/streams/memory.py", line 106, in receive_nowait
    raise WouldBlock
anyio.WouldBlock

During handling of the above exception, another exception occurred:

Traceback (most recent call last):
  File "/home/n8/.local/lib/python3.10/site-packages/anyio/streams/memory.py", line 124, in receive
    return receiver.item
AttributeError: 'MemoryObjectItemReceiver' object has no attribute 'item'

During handling of the above exception, another exception occurred:

Traceback (most recent call last):
  File "/home/n8/.local/lib/python3.10/site-packages/starlette/middleware/base.py", line 157, in call_next
    message = await recv_stream.receive()
  File "/home/n8/.local/lib/python3.10/site-packages/anyio/streams/memory.py", line 126, in receive
    raise EndOfStream
anyio.EndOfStream

During handling of the above exception, another exception occurred:

Traceback (most recent call last):
  File "/home/n8/Documents/capstone/OSUCS461-ExitTicket/OSUCS461/main.py", line 32, in dispatch
    response = await call_next(request)
  File "/home/n8/.local/lib/python3.10/site-packages/starlette/middleware/base.py", line 163, in call_next
    raise app_exc
  File "/home/n8/.local/lib/python3.10/site-packages/starlette/middleware/base.py", line 149, in coro
    await self.app(scope, receive_or_disconnect, send_no_error)
  File "/home/n8/.local/lib/python3.10/site-packages/starlette/middleware/exceptions.py", line 62, in __call__
    await wrap_app_handling_exceptions(self.app, conn)(scope, receive, send)
  File "/home/n8/.local/lib/python3.10/site-packages/starlette/_exception_handler.py", line 53, in wrapped_app
    raise exc
  File "/home/n8/.local/lib/python3.10/site-packages/starlette/_exception_handler.py", line 42, in wrapped_app
    await app(scope, receive, sender)
  File "/home/n8/.local/lib/python3.10/site-packages/starlette/routing.py", line 715, in __call__
    await self.middleware_stack(scope, receive, send)
  File "/home/n8/.local/lib/python3.10/site-packages/starlette/routing.py", line 735, in app
    await route.handle(scope, receive, send)
  File "/home/n8/.local/lib/python3.10/site-packages/starlette/routing.py", line 288, in handle
    await self.app(scope, receive, send)
  File "/home/n8/.local/lib/python3.10/site-packages/starlette/routing.py", line 76, in app
    await wrap_app_handling_exceptions(app, request)(scope, receive, send)
  File "/home/n8/.local/lib/python3.10/site-packages/starlette/_exception_handler.py", line 59, in wrapped_app
    response = await handler(conn, exc)
  File "/home/n8/.local/lib/python3.10/site-packages/fastapi/exception_handlers.py", line 15, in http_exception_handler
    return JSONResponse(
  File "/home/n8/.local/lib/python3.10/site-packages/starlette/responses.py", line 180, in __init__
    super().__init__(content, status_code, headers, media_type, background)
  File "/home/n8/.local/lib/python3.10/site-packages/starlette/responses.py", line 43, in __init__
    self.body = self.render(content)
  File "/home/n8/.local/lib/python3.10/site-packages/starlette/responses.py", line 183, in render
    return json.dumps(
  File "/usr/lib/python3.10/json/__init__.py", line 238, in dumps
    **kw).encode(obj)
  File "/usr/lib/python3.10/json/encoder.py", line 199, in encode
    chunks = self.iterencode(o, _one_shot=True)
  File "/usr/lib/python3.10/json/encoder.py", line 257, in iterencode
    return _iterencode(o, 0)
  File "/usr/lib/python3.10/json/encoder.py", line 179, in default
    raise TypeError(f'Object of type {o.__class__.__name__} '
TypeError: Object of type AttributeError is not JSON serializable

2024-12-10 19:28:44,449 - fastAPI - INFO - HP-API - local - Completed request in 0.0163 seconds
2024-12-10 19:30:46,136 - fastAPI - INFO - HP-API - local - Incoming request: POST http://127.0.0.1:8855/v1/users.
2024-12-10 19:30:46,139 - fastAPI - INFO - HP-API - local - Handling function: write_user
2024-12-10 19:30:46,158 - fastAPI - ERROR - HP-API - local - Error processing request. Request was handled by: write_user 
Method: POST - URL: http://127.0.0.1:8855/v1/users - Headers: Headers({'host': '127.0.0.1:8855', 'user-agent': 'Mozilla/5.0 (X11; Linux x86_64; rv:133.0) Gecko/20100101 Firefox/133.0', 'accept': 'application/json', 'accept-language': 'en-US,en;q=0.5', 'accept-encoding': 'gzip, deflate, br, zstd', 'referer': 'http://127.0.0.1:8855/docs', 'content-type': 'application/json', 'content-length': '43', 'origin': 'http://127.0.0.1:8855', 'connection': 'keep-alive', 'sec-fetch-dest': 'empty', 'sec-fetch-mode': 'cors', 'sec-fetch-site': 'same-origin', 'priority': 'u=0'}) 
Stack Trace: 'WriteUser' object has no attribute 'username'
Traceback (most recent call last):
  File "/home/n8/.local/lib/python3.10/site-packages/anyio/streams/memory.py", line 111, in receive
    return self.receive_nowait()
  File "/home/n8/.local/lib/python3.10/site-packages/anyio/streams/memory.py", line 106, in receive_nowait
    raise WouldBlock
anyio.WouldBlock

During handling of the above exception, another exception occurred:

Traceback (most recent call last):
  File "/home/n8/.local/lib/python3.10/site-packages/anyio/streams/memory.py", line 124, in receive
    return receiver.item
AttributeError: 'MemoryObjectItemReceiver' object has no attribute 'item'

During handling of the above exception, another exception occurred:

Traceback (most recent call last):
  File "/home/n8/.local/lib/python3.10/site-packages/starlette/middleware/base.py", line 157, in call_next
    message = await recv_stream.receive()
  File "/home/n8/.local/lib/python3.10/site-packages/anyio/streams/memory.py", line 126, in receive
    raise EndOfStream
anyio.EndOfStream

During handling of the above exception, another exception occurred:

Traceback (most recent call last):
  File "/home/n8/Documents/capstone/OSUCS461-ExitTicket/OSUCS461/main.py", line 32, in dispatch
    response = await call_next(request)
  File "/home/n8/.local/lib/python3.10/site-packages/starlette/middleware/base.py", line 163, in call_next
    raise app_exc
  File "/home/n8/.local/lib/python3.10/site-packages/starlette/middleware/base.py", line 149, in coro
    await self.app(scope, receive_or_disconnect, send_no_error)
  File "/home/n8/.local/lib/python3.10/site-packages/starlette/middleware/exceptions.py", line 62, in __call__
    await wrap_app_handling_exceptions(self.app, conn)(scope, receive, send)
  File "/home/n8/.local/lib/python3.10/site-packages/starlette/_exception_handler.py", line 53, in wrapped_app
    raise exc
  File "/home/n8/.local/lib/python3.10/site-packages/starlette/_exception_handler.py", line 42, in wrapped_app
    await app(scope, receive, sender)
  File "/home/n8/.local/lib/python3.10/site-packages/starlette/routing.py", line 715, in __call__
    await self.middleware_stack(scope, receive, send)
  File "/home/n8/.local/lib/python3.10/site-packages/starlette/routing.py", line 735, in app
    await route.handle(scope, receive, send)
  File "/home/n8/.local/lib/python3.10/site-packages/starlette/routing.py", line 288, in handle
    await self.app(scope, receive, send)
  File "/home/n8/.local/lib/python3.10/site-packages/starlette/routing.py", line 76, in app
    await wrap_app_handling_exceptions(app, request)(scope, receive, send)
  File "/home/n8/.local/lib/python3.10/site-packages/starlette/_exception_handler.py", line 53, in wrapped_app
    raise exc
  File "/home/n8/.local/lib/python3.10/site-packages/starlette/_exception_handler.py", line 42, in wrapped_app
    await app(scope, receive, sender)
  File "/home/n8/.local/lib/python3.10/site-packages/starlette/routing.py", line 73, in app
    response = await f(request)
  File "/home/n8/.local/lib/python3.10/site-packages/fastapi/routing.py", line 301, in app
    raw_response = await run_endpoint_function(
  File "/home/n8/.local/lib/python3.10/site-packages/fastapi/routing.py", line 212, in run_endpoint_function
    return await dependant.call(**values)
  File "/home/n8/Documents/capstone/OSUCS461-ExitTicket/OSUCS461/Routers/v1.py", line 31, in write_user
    uuid = UserLogic.write(user.username, user.time_created)
  File "/home/n8/.local/lib/python3.10/site-packages/pydantic/main.py", line 856, in __getattr__
    raise AttributeError(f'{type(self).__name__!r} object has no attribute {item!r}')
AttributeError: 'WriteUser' object has no attribute 'username'

2024-12-10 19:30:46,184 - fastAPI - INFO - HP-API - local - Completed request in 0.0447 seconds
